Workbook

Sheet Summary
A1: Navin Fluorine International Ltd | Equity Research Summary
A2: Integrated financial model & valuation. Consolidated figures, Rs Crore. Base year FY2026 (audited results); forecast FY2027-FY2033.
A4: Company snapshot
A5: Navin Fluorine International Ltd (NSE: NAVINFLUOR | BSE: 532504) is a leading Indian fluorochemicals company with four business lines - Refrigerant gases (HFCs/R-32), Inorganic fluorides, Specialty fluorochemicals (HPP), and CDMO/CRAMS (contract development & manufacturing). It is one of the few integrated fluorination players with captive Anhydrous Hydrofluoric Acid (AHF) capacity, serving pharma, agro and industrial customers globally.
A8: Market data (as of 25-Jun-2026)
A9: Current price (Rs) | B9: 7609 | D9: Market capitalisation (Rs Cr) | E9: 39032
A10: Shares outstanding (Cr) | B10: ='Working Schedules'!G23 | D10: Face value (Rs) | E10: 2
A11: 52-week high / low (Rs) | B11: 7,744 / 4,498 | D11: Book value (Rs/share) | E11: 775
A12: P/E - FY26 (x) | B12: =B9/'Profit & Loss'!G22 | D12: Price / Book (x) | E12: 9.8
A13: Beta (levered) | B13: ='Beta Calculation'!B22 | D13: Dividend yield (%) | E13: 0.002
A14: Consensus analyst target (Rs) | B14: 7386 | D14: India 10Y G-sec / Rf (%) | E14: 0.068
A16: Our target price (Rs) | B16: ='Valuation Summary'!D35 | D16: Recommendation | E16: ='Valuation Summary'!D38
A19: Key financials (Rs Cr) | B19: FY2021A | C19: FY2022A | D19: FY2023A | E19: FY2024A | F19: FY2025A | G19: FY2026A | H19: FY2027E | I19: FY2028E | J19: FY2029E | K19: FY2030E | L19: FY2031E | M19: FY2032E | N19: FY2033E
A20: Revenue | B20: ='Profit & Loss'!B4 | C20: ='Profit & Loss'!C4 | D20: ='Profit & Loss'!D4 | E20: ='Profit & Loss'!E4 | F20: ='Profit & Loss'!F4 | G20: ='Profit & Loss'!G4 | H20: ='Profit & Loss'!H4 | I20: ='Profit & Loss'!I4 | ... N20: ='Profit & Loss'!N4
A21: EBITDA | B21: ='Profit & Loss'!B10 | C21: ='Profit & Loss'!C10 | D21: ='Profit & Loss'!D10 | E21: ='Profit & Loss'!E10 | F21: ='Profit & Loss'!F10 | G21: ='Profit & Loss'!G10 | H21: ='Profit & Loss'!H10 | I21: ='Profit & Loss'!I10 | ... N21: ='Profit & Loss'!N10
A22: EBITDA margin (%) | B22: ='Profit & Loss'!B11 | C22: ='Profit & Loss'!C11 | D22: ='Profit & Loss'!D11 | E22: ='Profit & Loss'!E11 | F22: ='Profit & Loss'!F11 | G22: ='Profit & Loss'!G11 | H22: ='Profit & Loss'!H11 | I22: ='Profit & Loss'!I11 | ... N22: ='Profit & Loss'!N11
A23: EBIT | B23: ='Profit & Loss'!B13 | C23: ='Profit & Loss'!C13 | D23: ='Profit & Loss'!D13 | E23: ='Profit & Loss'!E13 | F23: ='Profit & Loss'!F13 | G23: ='Profit & Loss'!G13 | H23: ='Profit & Loss'!H13 | I23: ='Profit & Loss'!I13 | ... N23: ='Profit & Loss'!N13
A24: PAT | B24: ='Profit & Loss'!B21 | C24: ='Profit & Loss'!C21 | D24: ='Profit & Loss'!D21 | E24: ='Profit & Loss'!E21 | F24: ='Profit & Loss'!F21 | G24: ='Profit & Loss'!G21 | H24: ='Profit & Loss'!H21 | I24: ='Profit & Loss'!I21 | ... N24: ='Profit & Loss'!N21
A25: EPS (Rs) | B25: ='Profit & Loss'!B22 | C25: ='Profit & Loss'!C22 | D25: ='Profit & Loss'!D22 | E25: ='Profit & Loss'!E22 | F25: ='Profit & Loss'!F22 | G25: ='Profit & Loss'!G22 | H25: ='Profit & Loss'!H22 | I25: ='Profit & Loss'!I22 | ... N25: ='Profit & Loss'!N22
A26: ROE (%) | B26: ='Ratio Analysis'!B17 | C26: ='Ratio Analysis'!C17 | D26: ='Ratio Analysis'!D17 | E26: ='Ratio Analysis'!E17 | F26: ='Ratio Analysis'!F17 | G26: ='Ratio Analysis'!G17 | H26: ='Ratio Analysis'!H17 | I26: ='Ratio Analysis'!I17 | ... N26: ='Ratio Analysis'!N17
A27: ROCE (%) | B27: ='Ratio Analysis'!B18 | C27: ='Ratio Analysis'!C18 | D27: ='Ratio Analysis'!D18 | E27: ='Ratio Analysis'!E18 | F27: ='Ratio Analysis'!F18 | G27: ='Ratio Analysis'!G18 | H27: ='Ratio Analysis'!H18 | I27: ='Ratio Analysis'!I18 | ... N27: ='Ratio Analysis'!N18
A28: Net debt / (cash) | B28: ='Working Schedules'!B28 | C28: ='Working Schedules'!C28 | D28: ='Working Schedules'!D28 | E28: ='Working Schedules'!E28 | F28: ='Working Schedules'!F28 | G28: ='Working Schedules'!G28 | H28: ='Working Schedules'!H28 | I28: ='Working Schedules'!I28 | ... N28: ='Working Schedules'!N28
A29: FCFF | H29: =DCF!B26 | I29: =DCF!C26 | J29: =DCF!D26 | K29: =DCF!E26 | L29: =DCF!F26 | M29: =DCF!G26 | N29: =DCF!H26
A31: Investment thesis & key drivers
A32: + Structural growth: ~15% revenue CAGR FY26-33 driven by HPP (R-32/HFOs), CDMO/CRAMS ramp (cGMP-4, MPP), agro-specialties and capacity expansion at Dahej & Surat.
A33: + Premium franchise: scarcity value as an integrated fluorination + AHF player; high-value specialty mix lifted FY26 EBITDA margin to 32.6% and PAT 2.3x YoY.
A34: + Strong balance sheet: Rs750 Cr QIP (Jul-2025) funds the capex cycle; company operates near net-cash with comfortable interest cover.
A35: - Valuation: trades at ~58x trailing P/E and ~9.8x book; our DCF (WACC ~11.7%, g 5.5%) and peer-relative valuation both sit below the current price.
A36: - Risks: customer concentration in CDMO, raw-material/fluorspar pricing, refrigerant cycle, forex, and execution on large projects.
A37: > Net view: Rating reflects rich valuation, not business quality. Fair value range Rs 4,000-5,500; accumulate on meaningful corrections.

Sheet Valuation Summary
A1: Navin Fluorine International Ltd | Valuation Summary (DCF + Relative)
A2: Rs Crore / Rs per share. Combines the intrinsic FCFF DCF with peer relative valuation. Market data as of late-June 2026.
A4: A. DCF (FCFF) Valuation
A5: Enterprise value (Rs Cr) | B5: =DCF!B34
A6: Equity value (Rs Cr) | B6: =DCF!B36
A7: DCF intrinsic value per share (Rs) | B7: =DCF!B38
A9: B. Relative Valuation - peer multiples
A10: Peer (Indian specialty chemicals) | B10: Mkt Cap (Cr) | C10: EV (Cr) | D10: P/E (x) | E10: EV/EBITDA (x) | F10: EV/Sales (x)
A11: SRF Ltd | B11: 81010 | C11: 87000 | D11: 44.7 | E11: 24 | F11: 5.3
A12: PI Industries | B12: 46256 | C12: 42587 | D12: 31 | E12: 21 | F12: 5
A13: Gujarat Fluorochemicals | B13: 32000 | C13: 36000 | D13: 50 | E13: 26 | F13: 6.5
A14: Aarti Industries | B14: 17570 | C14: 25000 | D14: 42.6 | E14: 22 | F14: 3.2
A15: Vinati Organics | B15: 14174 | C15: 14000 | D15: 32.4 | E15: 22 | F15: 6
A16: Peer median | D16: =MEDIAN(D11:D15) | E16: =MEDIAN(E11:E15) | F16: =MEDIAN(F11:F15)
A18: Navin FY27E metrics
A19: FY27E EPS (Rs) | B19: ='Profit & Loss'!H22
A20: FY27E EBITDA (Rs Cr) | B20: ='Profit & Loss'!H10
A21: FY27E Revenue (Rs Cr) | B21: ='Profit & Loss'!H4
A22: Net debt FY26 (Rs Cr) | B22: ='Working Schedules'!G28
A23: No. of shares (Cr) | B23: ='Working Schedules'!G23
A25: Implied value / share - P/E method | B25: =D16*B19
A26: Implied value / share - EV/EBITDA method | B26: =(E16*B20-B22)/B23
A27: Implied value / share - EV/Sales method | B27: =(F16*B21-B22)/B23
A29: C. Blended Target & Recommendation
A30: Method | B30: Value/share | C30: Weight | D30: Weighted
A31: DCF (FCFF) | B31: =B7 | C31: 0.4 | D31: =B31*C31
A32: Relative - P/E | B32: =B25 | C32: 0.3 | D32: =B32*C32
A33: Relative - EV/EBITDA | B33: =B26 | C33: 0.2 | D33: =B33*C33
A34: Relative - EV/Sales | B34: =B27 | C34: 0.1 | D34: =B34*C34
A35: Target price (weighted, Rs) | D35: =SUM(D31:D34)
A36: Current market price (Rs) | D36: =DCF!B39
A37: Upside / (downside) | D37: =D35/D36-1
A38: Recommendation | D38: =IF(D37>0.15,"BUY",IF(D37>-0.1,"HOLD","REDUCE"))
A40: Conclusion: Navin Fluorine is a high-quality, structurally-growing fluorochemicals & CDMO franchise, but at the current price it trades at a marked premium to both its intrinsic DCF value and peer-implied multiples (P/E ~58x). The blended fair value therefore sits below the market price, implying limited margin of safety. The premium reflects the market pricing in long-duration growth optionality (fluorination scarcity, HPP/CDMO ramp, capacity expansion). Upside risk exists if the high-growth phase sustains beyond the explicit period; downside risk if margins normalise. Rating reflects valuation, not business quality.

Sheet DCF
A1: Navin Fluorine International Ltd | Discounted Cash Flow (FCFF)
A2: Rs Crore unless stated. Free Cash Flow to Firm discounted at WACC; two-stage (explicit FY27-FY33 + Gordon terminal value).
A4: Cost of Capital (WACC)
A5: Risk-free rate (Rf, India 10Y G-sec) | B5: 0.068
A6: Equity risk premium (ERP) | B6: 0.06
A7: Levered beta | B7: ='Beta Calculation'!B22
A8: Cost of equity (Ke = Rf + beta x ERP) | B8: =B5+B7*B6
A9: Pre-tax cost of debt (Kd) | B9: 0.075
A10: Marginal tax rate | B10: 0.25
A11: After-tax cost of debt = Kd x (1-tax) | B11: =B9*(1-B10)
A12: Market value of equity (Rs Cr) | B12: 39032
A13: Market value of debt (Rs Cr) | B13: ='Balance Sheet'!G18
A14: Weight of equity | B14: =B12/(B12+B13)
A15: Weight of debt | B15: =B13/(B12+B13)
A16: WACC | B16: =B14*B8+B15*B11
A17: Terminal growth rate (g) | B17: 0.055
A19: Free Cash Flow to Firm | B19: FY2027E | C19: FY2028E | D19: FY2029E | E19: FY2030E | F19: FY2031E | G19: FY2032E | H19: FY2033E
A20: EBIT | B20: ='Profit & Loss'!H13 | C20: ='Profit & Loss'!I13 | D20: ='Profit & Loss'!J13 | E20: ='Profit & Loss'!K13 | F20: ='Profit & Loss'!L13 | G20: ='Profit & Loss'!M13 | H20: ='Profit & Loss'!N13
A21: Less: Tax on EBIT | B21: =B20*$B$10 | C21: =C20*$B$10 | D21: =D20*$B$10 | E21: =E20*$B$10 | F21: =F20*$B$10 | G21: =G20*$B$10 | H21: =H20*$B$10
A22: NOPAT | B22: =B20-B21 | C22: =C20-C21 | D22: =D20-D21 | E22: =E20-E21 | F22: =F20-F21 | G22: =G20-G21 | H22: =H20-H21
A23: Add: Depreciation & amortisation | B23: ='Profit & Loss'!H12 | C23: ='Profit & Loss'!I12 | D23: ='Profit & Loss'!J12 | E23: ='Profit & Loss'!K12 | F23: ='Profit & Loss'!L12 | G23: ='Profit & Loss'!M12 | H23: ='Profit & Loss'!N12
A24: Less: Capital expenditure | B24: =Assumptions!H11 | C24: =Assumptions!I11 | D24: =Assumptions!J11 | E24: =Assumptions!K11 | F24: =Assumptions!L11 | G24: =Assumptions!M11 | H24: =Assumptions!N11
A25: Less: Increase in net working capital | B25: ='Working Capital Schedule'!H12 | C25: ='Working Capital Schedule'!I12 | D25: ='Working Capital Schedule'!J12 | E25: ='Working Capital Schedule'!K12 | F25: ='Working Capital Schedule'!L12 | G25: ='Working Capital Schedule'!M12 | H25: ='Working Capital Schedule'!N12
A26: Free cash flow to firm (FCFF) | B26: =B22+B23-B24-B25 | C26: =C22+C23-C24-C25 | D26: =D22+D23-D24-D25 | E26: =E22+E23-E24-E25 | F26: =F22+F23-F24-F25 | G26: =G22+G23-G24-G25 | H26: =H22+H23-H24-H25
A27: Discount period | B27: 1 | C27: 2 | D27: 3 | E27: 4 | F27: 5 | G27: 6 | H27: 7
A28: Discount factor | B28: =1/(1+$B$16)^B27 | C28: =1/(1+$B$16)^C27 | D28: =1/(1+$B$16)^D27 | E28: =1/(1+$B$16)^E27 | F28: =1/(1+$B$16)^F27 | G28: =1/(1+$B$16)^G27 | H28: =1/(1+$B$16)^H27
A29: PV of FCFF | B29: =B26*B28 | C29: =C26*C28 | D29: =D26*D28 | E29: =E26*E28 | F29: =F26*F28 | G29: =G26*G28 | H29: =H26*H28
A31: PV of explicit FCFF (FY27-FY33) | B31: =SUM(B29:H29)
A32: Terminal value = FCFF(FY33) x (1+g) / (WACC-g) | B32: =H26*(1+B17)/(B16-B17)
A33: PV of terminal value | B33: =B32*H28
A34: Enterprise value (EV) | B34: =B31+B33
A35: Less: Net debt (FY26) | B35: ='Working Schedules'!G28
A36: Equity value | B36: =B34-B35
A37: No. of equity shares (Cr) | B37: ='Working Schedules'!G23
A38: Intrinsic value per share (Rs) | B38: =B36/B37
A39: Current market price (Rs) | B39: 7609
A40: Upside / (downside) | B40: =B38/B39-1
A41: Implied terminal value as % of EV | B41: =B33/B34
A44: Sensitivity - intrinsic value per share (Rs)
A45: WACC \ Terminal g | B45: 0.045 | C45: 0.05 | D45: 0.055 | E45: 0.06 | F45: 0.065
...

Sheet Ratio Analysis
A1: Navin Fluorine International Ltd | Ratio Analysis
A2: Historical and forecast ratios. All figures derived from the integrated statements (links shown in green).
A3: Particulars | B3: FY2021A | C3: FY2022A | D3: FY2023A | E3: FY2024A | F3: FY2025A | G3: FY2026A | H3: FY2027E | I3: FY2028E | J3: FY2029E | K3: FY2030E | L3: FY2031E | M3: FY2032E | N3: FY2033E
A4: Growth (%)
A5: Revenue growth | C5: =IF('Profit & Loss'!B4=0,"",'Profit & Loss'!C4/'Profit & Loss'!B4-1) | D5: =IF('Profit & Loss'!C4=0,"",'Profit & Loss'!D4/'Profit & Loss'!C4-1) | E5: =IF('Profit & Loss'!D4=0,"",'Profit & Loss'!E4/'Profit & Loss'!D4-1) | F5: =IF('Profit & Loss'!E4=0,"",'Profit & Loss'!F4/'Profit & Loss'!E4-1) | G5: =IF('Profit & Loss'!F4=0,"",'Profit & Loss'!G4/'Profit & Loss'!F4-1) | H5: =IF('Profit & Loss'!G4=0,"",'Profit & Loss'!H4/'Profit & Loss'!G4-1) | I5: =IF('Profit & Loss'!H4=0,"",'Profit & Loss'!I4/'Profit & Loss'!H4-1) | J5: =IF('Profit & Loss'!I4=0,"",'Profit & Loss'!J4/'Profit & Loss'!I4-1) | ... N5: =IF('Profit & Loss'!M4=0,"",'Profit & Loss'!N4/'Profit & Loss'!M4-1)
A6: EBITDA growth | C6: =IF('Profit & Loss'!B10=0,"",'Profit & Loss'!C10/'Profit & Loss'!B10-1) | D6: =IF('Profit & Loss'!C10=0,"",'Profit & Loss'!D10/'Profit & Loss'!C10-1) | E6: =IF('Profit & Loss'!D10=0,"",'Profit & Loss'!E10/'Profit & Loss'!D10-1) | F6: =IF('Profit & Loss'!E10=0,"",'Profit & Loss'!F10/'Profit & Loss'!E10-1) | G6: =IF('Profit & Loss'!F10=0,"",'Profit & Loss'!G10/'Profit & Loss'!F10-1) | H6: =IF('Profit & Loss'!G10=0,"",'Profit & Loss'!H10/'Profit & Loss'!G10-1) | I6: =IF('Profit & Loss'!H10=0,"",'Profit & Loss'!I10/'Profit & Loss'!H10-1) | J6: =IF('Profit & Loss'!I10=0,"",'Profit & Loss'!J10/'Profit & Loss'!I10-1) | ... N6: =IF('Profit & Loss'!M10=0,"",'Profit & Loss'!N10/'Profit & Loss'!M10-1)
A7: EBIT growth | C7: =IF('Profit & Loss'!B13=0,"",'Profit & Loss'!C13/'Profit & Loss'!B13-1) | D7: =IF('Profit & Loss'!C13=0,"",'Profit & Loss'!D13/'Profit & Loss'!C13-1) | E7: =IF('Profit & Loss'!D13=0,"",'Profit & Loss'!E13/'Profit & Loss'!D13-1) | F7: =IF('Profit & Loss'!E13=0,"",'Profit & Loss'!F13/'Profit & Loss'!E13-1) | G7: =IF('Profit & Loss'!F13=0,"",'Profit & Loss'!G13/'Profit & Loss'!F13-1) | H7: =IF('Profit & Loss'!G13=0,"",'Profit & Loss'!H13/'Profit & Loss'!G13-1) | I7: =IF('Profit & Loss'!H13=0,"",'Profit & Loss'!I13/'Profit & Loss'!H13-1) | J7: =IF('Profit & Loss'!I13=0,"",'Profit & Loss'!J13/'Profit & Loss'!I13-1) | ... N7: =IF('Profit & Loss'!M13=0,"",'Profit & Loss'!N13/'Profit & Loss'!M13-1)
A8: PAT growth | C8: =IF('Profit & Loss'!B21=0,"",'Profit & Loss'!C21/'Profit & Loss'!B21-1) | D8: =IF('Profit & Loss'!C21=0,"",'Profit & Loss'!D21/'Profit & Loss'!C21-1) | E8: =IF('Profit & Loss'!D21=0,"",'Profit & Loss'!E21/'Profit & Loss'!D21-1) | F8: =IF('Profit & Loss'!E21=0,"",'Profit & Loss'!F21/'Profit & Loss'!E21-1) | G8: =IF('Profit & Loss'!F21=0,"",'Profit & Loss'!G21/'Profit & Loss'!F21-1) | H8: =IF('Profit & Loss'!G21=0,"",'Profit & Loss'!H21/'Profit & Loss'!G21-1) | I8: =IF('Profit & Loss'!H21=0,"",'Profit & Loss'!I21/'Profit & Loss'!H21-1) | J8: =IF('Profit & Loss'!I21=0,"",'Profit & Loss'!J21/'Profit & Loss'!I21-1) | ... N8: =IF('Profit & Loss'!M21=0,"",'Profit & Loss'!N21/'Profit & Loss'!M21-1)
A10: Profitability margins (%)
A11: Gross margin | B11: =('Profit & Loss'!B4-'Profit & Loss'!B6)/'Profit & Loss'!B4 | C11: =('Profit & Loss'!C4-'Profit & Loss'!C6)/'Profit & Loss'!C4 | D11: =('Profit & Loss'!D4-'Profit & Loss'!D6)/'Profit & Loss'!D4 | E11: =('Profit & Loss'!E4-'Profit & Loss'!E6)/'Profit & Loss'!E4 | F11: =('Profit & Loss'!F4-'Profit & Loss'!F6)/'Profit & Loss'!F4 | G11: =('Profit & Loss'!G4-'Profit & Loss'!G6)/'Profit & Loss'!G4 | H11: =('Profit & Loss'!H4-'Profit & Loss'!H6)/'Profit & Loss'!H4 | I11: =('Profit & Loss'!I4-'Profit & Loss'!I6)/'Profit & Loss'!I4 | ... N11: =('Profit & Loss'!N4-'Profit & Loss'!N6)/'Profit & Loss'!N4
A12: EBITDA margin | B12: ='Profit & Loss'!B10/'Profit & Loss'!B4 | C12: ='Profit & Loss'!C10/'Profit & Loss'!C4 | D12: ='Profit & Loss'!D10/'Profit & Loss'!D4 | E12: ='Profit & Loss'!E10/'Profit & Loss'!E4 | F12: ='Profit & Loss'!F10/'Profit & Loss'!F4 | G12: ='Profit & Loss'!G10/'Profit & Loss'!G4 | H12: ='Profit & Loss'!H10/'Profit & Loss'!H4 | I12: ='Profit & Loss'!I10/'Profit & Loss'!I4 | ... N12: ='Profit & Loss'!N10/'Profit & Loss'!N4
A13: EBIT margin | B13: ='Profit & Loss'!B13/'Profit & Loss'!B4 | C13: ='Profit & Loss'!C13/'Profit & Loss'!C4 | D13: ='Profit & Loss'!D13/'Profit & Loss'!D4 | E13: ='Profit & Loss'!E13/'Profit & Loss'!E4 | F13: ='Profit & Loss'!F13/'Profit & Loss'!F4 | G13: ='Profit & Loss'!G13/'Profit & Loss'!G4 | H13: ='Profit & Loss'!H13/'Profit & Loss'!H4 | I13: ='Profit & Loss'!I13/'Profit & Loss'!I4 | ... N13: ='Profit & Loss'!N13/'Profit & Loss'!N4
A14: PAT margin | B14: ='Profit & Loss'!B21/'Profit & Loss'!B4 | C14: ='Profit & Loss'!C21/'Profit & Loss'!C4 | D14: ='Profit & Loss'!D21/'Profit & Loss'!D4 | E14: ='Profit & Loss'!E21/'Profit & Loss'!E4 | F14: ='Profit & Loss'!F21/'Profit & Loss'!F4 | G14: ='Profit & Loss'!G21/'Profit & Loss'!G4 | H14: ='Profit & Loss'!H21/'Profit & Loss'!H4 | I14: ='Profit & Loss'!I21/'Profit & Loss'!I4 | ... N14: ='Profit & Loss'!N21/'Profit & Loss'!N4
A16: Return ratios (%)
A17: Return on equity (ROE) | B17: ='Profit & Loss'!B21/('Balance Sheet'!B16+'Balance Sheet'!B17) | C17: ='Profit & Loss'!C21/((('Balance Sheet'!C16+'Balance Sheet'!C17)+('Balance Sheet'!B16+'Balance Sheet'!B17))/2) | D17: ='Profit & Loss'!D21/((('Balance Sheet'!D16+'Balance Sheet'!D17)+('Balance Sheet'!C16+'Balance Sheet'!C17))/2) | E17: ='Profit & Loss'!E21/((('Balance Sheet'!E16+'Balance Sheet'!E17)+('Balance Sheet'!D16+'Balance Sheet'!D17))/2) | F17: ='Profit & Loss'!F21/((('Balance Sheet'!F16+'Balance Sheet'!F17)+('Balance Sheet'!E16+'Balance Sheet'!E17))/2) | G17: ='Profit & Loss'!G21/((('Balance Sheet'!G16+'Balance Sheet'!G17)+('Balance Sheet'!F16+'Balance Sheet'!F17))/2) | H17: ='Profit & Loss'!H21/((('Balance Sheet'!H16+'Balance Sheet'!H17)+('Balance Sheet'!G16+'Balance Sheet'!G17))/2) | I17: ='Profit & Loss'!I21/((('Balance Sheet'!I16+'Balance Sheet'!I17)+('Balance Sheet'!H16+'Balance Sheet'!H17))/2) | J17: ='Profit & Loss'!J21/((('Balance Sheet'!J16+'Balance Sheet'!J17)+('Balance Sheet'!I16+'Balance Sheet'!I17))/2) | ... N17: ='Profit & Loss'!N21/((('Balance Sheet'!N16+'Balance Sheet'!N17)+('Balance Sheet'!M16+'Balance Sheet'!M17))/2)
A18: Return on capital employed (ROCE) | B18: ='Profit & Loss'!B13/('Balance Sheet'!B16+'Balance Sheet'!B17+'Balance Sheet'!B18) | C18: ='Profit & Loss'!C13/((('Balance Sheet'!C16+'Balance Sheet'!C17+'Balance Sheet'!C18)+('Balance Sheet'!B16+'Balance Sheet'!B17+'Balance Sheet'!B18))/2) | D18: ='Profit & Loss'!D13/((('Balance Sheet'!D16+'Balance Sheet'!D17+'Balance Sheet'!D18)+('Balance Sheet'!C16+'Balance Sheet'!C17+'Balance Sheet'!C18))/2) | E18: ='Profit & Loss'!E13/((('Balance Sheet'!E16+'Balance Sheet'!E17+'Balance Sheet'!E18)+('Balance Sheet'!D16+'Balance Sheet'!D17+'Balance Sheet'!D18))/2) | F18: ='Profit & Loss'!F13/((('Balance Sheet'!F16+'Balance Sheet'!F17+'Balance Sheet'!F18)+('Balance Sheet'!E16+'Balance Sheet'!E17+'Balance Sheet'!E18))/2) | G18: ='Profit & Loss'!G13/((('Balance Sheet'!G16+'Balance Sheet'!G17+'Balance Sheet'!G18)+('Balance Sheet'!F16+'Balance Sheet'!F17+'Balance Sheet'!F18))/2) | H18: ='Profit & Loss'!H13/((('Balance Sheet'!H16+'Balance Sheet'!H17+'Balance Sheet'!H18)+('Balance Sheet'!G16+'Balance Sheet'!G17+'Balance Sheet'!G18))/2) | I18: ='Profit & Loss'!I13/((('Balance Sheet'!I16+'Balance Sheet'!I17+'Balance Sheet'!I18)+('Balance Sheet'!H16+'Balance Sheet'!H17+'Balance Sheet'!H18))/2) | J18: ='Profit & Loss'!J13/((('Balance Sheet'!J16+'Balance Sheet'!J17+'Balance Sheet'!J18)+('Balance Sheet'!I16+'Balance Sheet'!I17+'Balance Sheet'!I18))/2) | ... N18: ='Profit & Loss'!N13/((('Balance Sheet'!N16+'Balance Sheet'!N17+'Balance Sheet'!N18)+('Balance Sheet'!M16+'Balance Sheet'!M17+'Balance Sheet'!M18))/2)
A19: Return on invested capital (ROIC) | B19: ='Profit & Loss'!B13*(1-'Profit & Loss'!B20)/('Balance Sheet'!B16+'Balance Sheet'!B17+'Balance Sheet'!B18-'Balance Sheet'!B11) | C19: ='Profit & Loss'!C13*(1-'Profit & Loss'!C20)/((('Balance Sheet'!C16+'Balance Sheet'!C17+'Balance Sheet'!C18-'Balance Sheet'!C11)+('Balance Sheet'!B16+'Balance Sheet'!B17+'Balance Sheet'!B18-'Balance Sheet'!B11))/2) | D19: ='Profit & Loss'!D13*(1-'Profit & Loss'!D20)/((('Balance Sheet'!D16+'Balance Sheet'!D17+'Balance Sheet'!D18-'Balance Sheet'!D11)+('Balance Sheet'!C16+'Balance Sheet'!C17+'Balance Sheet'!C18-'Balance Sheet'!C11))/2) | E19: ='Profit & Loss'!E13*(1-'Profit & Loss'!E20)/((('Balance Sheet'!E16+'Balance Sheet'!E17+'Balance Sheet'!E18-'Balance Sheet'!E11)+('Balance Sheet'!D16+'Balance Sheet'!D17+'Balance Sheet'!D18-'Balance Sheet'!D11))/2) | F19: ='Profit & Loss'!F13*(1-'Profit & Loss'!F20)/((('Balance Sheet'!F16+'Balance Sheet'!F17+'Balance Sheet'!F18-'Balance Sheet'!F11)+('Balance Sheet'!E16+'Balance Sheet'!E17+'Balance Sheet'!E18-'Balance Sheet'!E11))/2) | G19: ='Profit & Loss'!G13*(1-'Profit & Loss'!G20)/((('Balance Sheet'!G16+'Balance Sheet'!G17+'Balance Sheet'!G18-'Balance Sheet'!G11)+('Balance Sheet'!F16+'Balance Sheet'!F17+'Balance Sheet'!F18-'Balance Sheet'!F11))/2) | H19: ='Profit & Loss'!H13*(1-'Profit & Loss'!H20)/((('Balance Sheet'!H16+'Balance Sheet'!H17+'Balance Sheet'!H18-'Balance Sheet'!H11)+('Balance Sheet'!G16+'Balance Sheet'!G17+'Balance Sheet'!G18-'Balance Sheet'!G11))/2) | I19: ='Profit & Loss'!I13*(1-'Profit & Loss'!I20)/((('Balance Sheet'!I16+'Balance Sheet'!I17+'Balance Sheet'!I18-'Balance Sheet'!I11)+('Balance Sheet'!H16+'Balance Sheet'!H17+'Balance Sheet'!H18-'Balance Sheet'!H11))/2) | J19: ='Profit & Loss'!J13*(1-'Profit & Loss'!J20)/((('Balance Sheet'!J16+'Balance Sheet'!J17+'Balance Sheet'!J18-'Balance Sheet'!J11)+('Balance Sheet'!I16+'Balance Sheet'!I17+'Balance Sheet'!I18-'Balance Sheet'!I11))/2) | ... N19: ='Profit & Loss'!N13*(1-'Profit & Loss'!N20)/((('Balance Sheet'!N16+'Balance Sheet'!N17+'Balance Sheet'!N18-'Balance Sheet'!N11)+('Balance Sheet'!M16+'Balance Sheet'!M17+'Balance Sheet'!M18-'Balance Sheet'!M11))/2)
A21: Efficiency
A22: Asset turnover (x) | B22: ='Profit & Loss'!B4/'Balance Sheet'!B13 | C22: ='Profit & Loss'!C4/(('Balance Sheet'!C13+'Balance Sheet'!B13)/2) | D22: ='Profit & Loss'!D4/(('Balance Sheet'!D13+'Balance Sheet'!C13)/2) | E22: ='Profit & Loss'!E4/(('Balance Sheet'!E13+'Balance Sheet'!D13)/2) | F22: ='Profit & Loss'!F4/(('Balance Sheet'!F13+'Balance Sheet'!E13)/2) | G22: ='Profit & Loss'!G4/(('Balance Sheet'!G13+'Balance Sheet'!F13)/2) | H22: ='Profit & Loss'!H4/(('Balance Sheet'!H13+'Balance Sheet'!G13)/2) | I22: ='Profit & Loss'!I4/(('Balance Sheet'!I13+'Balance Sheet'!H13)/2) | J22: ='Profit & Loss'!J4/(('Balance Sheet'!J13+'Balance Sheet'!I13)/2) | ... N22: ='Profit & Loss'!N4/(('Balance Sheet'!N13+'Balance Sheet'!M13)/2)
A23: Inventory days | B23: ='Working Capital Schedule'!B15 | C23: ='Working Capital Schedule'!C15 | D23: ='Working Capital Schedule'!D15 | E23: ='Working Capital Schedule'!E15 | F23: ='Working Capital Schedule'!F15 | G23: ='Working Capital Schedule'!G15 | H23: ='Working Capital Schedule'!H15 | I23: ='Working Capital Schedule'!I15 | ... N23: ='Working Capital Schedule'!N15
A24: Receivable days | B24: ='Working Capital Schedule'!B14 | C24: ='Working Capital Schedule'!C14 | D24: ='Working Capital Schedule'!D14 | E24: ='Working Capital Schedule'!E14 | F24: ='Working Capital Schedule'!F14 | G24: ='Working Capital Schedule'!G14 | H24: ='Working Capital Schedule'!H14 | I24: ='Working Capital Schedule'!I14 | ... N24: ='Working Capital Schedule'!N14
A25: Payable days | B25: ='Working Capital Schedule'!B16 | C25: ='Working Capital Schedule'!C16 | D25: ='Working Capital Schedule'!D16 | E25: ='Working Capital Schedule'!E16 | F25: ='Working Capital Schedule'!F16 | G25: ='Working Capital Schedule'!G16 | H25: ='Working Capital Schedule'!H16 | I25: ='Working Capital Schedule'!I16 | ... N25: ='Working Capital Schedule'!N16
A26: Cash conversion cycle (days) | B26: ='Working Capital Schedule'!B17 | C26: ='Working Capital Schedule'!C17 | D26: ='Working Capital Schedule'!D17 | E26: ='Working Capital Schedule'!E17 | F26: ='Working Capital Schedule'!F17 | G26: ='Working Capital Schedule'!G17 | H26: ='Working Capital Schedule'!H17 | I26: ='Working Capital Schedule'!I17 | ... N26: ='Working Capital Schedule'!N17
A28: Leverage
A29: Debt / Equity (x) | B29: ='Balance Sheet'!B18/('Balance Sheet'!B16+'Balance Sheet'!B17) | C29: ='Balance Sheet'!C18/('Balance Sheet'!C16+'Balance Sheet'!C17) | D29: ='Balance Sheet'!D18/('Balance Sheet'!D16+'Balance Sheet'!D17) | E29: ='Balance Sheet'!E18/('Balance Sheet'!E16+'Balance Sheet'!E17) | F29: ='Balance Sheet'!F18/('Balance Sheet'!F16+'Balance Sheet'!F17) | G29: ='Balance Sheet'!G18/('Balance Sheet'!G16+'Balance Sheet'!G17) | H29: ='Balance Sheet'!H18/('Balance Sheet'!H16+'Balance Sheet'!H17) | I29: ='Balance Sheet'!I18/('Balance Sheet'!I16+'Balance Sheet'!I17) | ... N29: ='Balance Sheet'!N18/('Balance Sheet'!N16+'Balance Sheet'!N17)
A30: Net debt / EBITDA (x) | B30: ='Working Schedules'!B28/'Profit & Loss'!B10 | C30: ='Working Schedules'!C28/'Profit & Loss'!C10 | D30: ='Working Schedules'!D28/'Profit & Loss'!D10 | E30: ='Working Schedules'!E28/'Profit & Loss'!E10 | F30: ='Working Schedules'!F28/'Profit & Loss'!F10 | G30: ='Working Schedules'!G28/'Profit & Loss'!G10 | H30: ='Working Schedules'!H28/'Profit & Loss'!H10 | I30: ='Working Schedules'!I28/'Profit & Loss'!I10 | ... N30: ='Working Schedules'!N28/'Profit & Loss'!N10
A31: Interest coverage (EBIT/interest, x) | B31: =IF('Profit & Loss'!B15=0,"",'Profit & Loss'!B13/'Profit & Loss'!B15) | C31: =IF('Profit & Loss'!C15=0,"",'Profit & Loss'!C13/'Profit & Loss'!C15) | D31: =IF('Profit & Loss'!D15=0,"",'Profit & Loss'!D13/'Profit & Loss'!D15) | E31: =IF('Profit & Loss'!E15=0,"",'Profit & Loss'!E13/'Profit & Loss'!E15) | F31: =IF('Profit & Loss'!F15=0,"",'Profit & Loss'!F13/'Profit & Loss'!F15) | G31: =IF('Profit & Loss'!G15=0,"",'Profit & Loss'!G13/'Profit & Loss'!G15) | H31: =IF('Profit & Loss'!H15=0,"",'Profit & Loss'!H13/'Profit & Loss'!H15) | I31: =IF('Profit & Loss'!I15=0,"",'Profit & Loss'!I13/'Profit & Loss'!I15) | ... N31: =IF('Profit & Loss'!N15=0,"",'Profit & Loss'!N13/'Profit & Loss'!N15)

Sheet Profit & Loss
A1: Navin Fluorine International Ltd | Consolidated Profit & Loss Statement
A2: Rs Crore. Historical FY21-FY26 from consolidated annual reports / audited results; FY27-FY33 forecast driven by the Assumptions sheet.
A3: Particulars | B3: FY2021A | C3: FY2022A | D3: FY2023A | E3: FY2024A | F3: FY2025A | G3: FY2026A | H3: FY2027E | I3: FY2028E | J3: FY2029E | K3: FY2030E | L3: FY2031E | M3: FY2032E | N3: FY2033E
A4: Revenue from operations | B4: 1179.39 | C4: 1453.36 | D4: 2077.4 | E4: 2065.01 | F4: 2349.38 | G4: 3314 | H4: =G4*(1+Assumptions!H5) | I4: =H4*(1+Assumptions!I5) | J4: =I4*(1+Assumptions!J5) | K4: =J4*(1+Assumptions!K5) | L4: =K4*(1+Assumptions!L5) | M4: =L4*(1+Assumptions!M5) | N4: =M4*(1+Assumptions!N5)
A5: Revenue growth (%) | C5: =IF(B4=0,"",C4/B4-1) | D5: =IF(C4=0,"",D4/C4-1) | E5: =IF(D4=0,"",E4/D4-1) | F5: =IF(E4=0,"",F4/E4-1) | G5: =IF(F4=0,"",G4/F4-1) | H5: =IF(G4=0,"",H4/G4-1) | I5: =IF(H4=0,"",I4/H4-1) | J5: =IF(I4=0,"",J4/I4-1) | ... N5: =IF(M4=0,"",N4/M4-1)
A6: Cost of materials consumed | B6: 537.37 | C6: 665.63 | D6: 896.01 | E6: 935.43 | F6: 1038.62 | G6: 1359 | H6: =H4*Assumptions!H6 | I6: =I4*Assumptions!I6 | J6: =J4*Assumptions!J6 | K6: =K4*Assumptions!K6 | L6: =L4*Assumptions!L6 | M6: =M4*Assumptions!M6 | N6: =N4*Assumptions!N6
A7: Employee benefit expense | B7: 141.7 | C7: 181.53 | D7: 249.41 | E7: 285.84 | F7: 296.67 | G7: 331 | H7: =H4*Assumptions!H7 | I7: =I4*Assumptions!I7 | J7: =J4*Assumptions!J7 | K7: =K4*Assumptions!K7 | L7: =L4*Assumptions!L7 | M7: =M4*Assumptions!M7 | N7: =N4*Assumptions!N7
A8: Other expenses | B8: 191.03 | C8: 251.39 | D8: 381.67 | E8: 445.46 | F8: 480.37 | G8: 542 | H8: =H4*Assumptions!H8 | I8: =I4*Assumptions!I8 | J8: =J4*Assumptions!J8 | K8: =K4*Assumptions!K8 | L8: =L4*Assumptions!L8 | M8: =M4*Assumptions!M8 | N8: =N4*Assumptions!N8
A9: Total operating expenses | B9: =SUM(B6:B8) | C9: =SUM(C6:C8) | D9: =SUM(D6:D8) | E9: =SUM(E6:E8) | F9: =SUM(F6:F8) | G9: =SUM(G6:G8) | H9: =SUM(H6:H8) | I9: =SUM(I6:I8) | ... N9: =SUM(N6:N8)
A10: EBITDA | B10: =B4-B9 | C10: =C4-C9 | D10: =D4-D9 | E10: =E4-E9 | F10: =F4-F9 | G10: =G4-G9 | H10: =H4-H9 | I10: =I4-I9 | ... N10: =N4-N9
A11: EBITDA margin (%) | B11: =IF(B4=0,"",B10/B4) | C11: =IF(C4=0,"",C10/C4) | D11: =IF(D4=0,"",D10/D4) | E11: =IF(E4=0,"",E10/E4) | F11: =IF(F4=0,"",F10/F4) | G11: =IF(G4=0,"",G10/G4) | H11: =IF(H4=0,"",H10/H4) | I11: =IF(I4=0,"",I10/I4) | ... N11: =IF(N4=0,"",N10/N4)
A12: Depreciation & amortisation | B12: 44.17 | C12: 47.9 | D12: 62.64 | E12: 96.16 | F12: 119.43 | G12: 149 | H12: ='Working Schedules'!H6 | I12: ='Working Schedules'!I6 | J12: ='Working Schedules'!J6 | K12: ='Working Schedules'!K6 | L12: ='Working Schedules'!L6 | M12: ='Working Schedules'!M6 | N12: ='Working Schedules'!N6
A13: EBIT | B13: =B10-B12 | C13: =C10-C12 | D13: =D10-D12 | E13: =E10-E12 | F13: =F10-F12 | G13: =G10-G12 | H13: =H10-H12 | I13: =I10-I12 | ... N13: =N10-N12
A14: Other income | B14: 79.04 | C14: 39.22 | D14: 35.73 | E14: 55.85 | F14: 43.73 | G14: 59 | H14: =H4*Assumptions!H9 | I14: =I4*Assumptions!I9 | J14: =J4*Assumptions!J9 | K14: =K4*Assumptions!K9 | L14: =L4*Assumptions!L9 | M14: =M4*Assumptions!M9 | N14: =N4*Assumptions!N9
A15: Finance costs | B15: 1.84 | C15: 1.9 | D15: 27.52 | E15: 74.56 | F15: 77.93 | G15: 118 | H15: ='Working Schedules'!H13 | I15: ='Working Schedules'!I13 | J15: ='Working Schedules'!J13 | K15: ='Working Schedules'!K13 | L15: ='Working Schedules'!L13 | M15: ='Working Schedules'!M13 | N15: ='Working Schedules'!N13
A16: Profit before exceptional items & tax | B16: =B13+B14-B15 | C16: =C13+C14-C15 | D16: =D13+D14-D15 | E16: =E13+E14-E15 | F16: =F13+F14-F15 | G16: =G13+G14-G15 | H16: =H13+H14-H15 | I16: =I13+I14-I15 | ... N16: =N13+N14-N15
A17: Exceptional items | B17: 15.51 | C17: 0 | D17: 0 | E17: 52.13 | F17: 0 | G17: 0 | H17: 0 | I17: 0 | J17: 0 | K17: 0 | L17: 0 | M17: 0 | N17: 0
A18: Profit before tax | B18: =B16+B17 | C18: =C16+C17 | D18: =D16+D17 | E18: =E16+E17 | F18: =F16+F17 | G18: =G16+G17 | H18: =H16+H17 | I18: =I16+I17 | ... N18: =N16+N17
A19: Tax expense | B19: 110.78 | C19: 81.15 | D19: 120.69 | E19: 65.03 | F19: 91.49 | G19: 209 | H19: =H18*Assumptions!H12 | I19: =I18*Assumptions!I12 | J19: =J18*Assumptions!J12 | K19: =K18*Assumptions!K12 | L19: =L18*Assumptions!L12 | M19: =M18*Assumptions!M12 | N19: =N18*Assumptions!N12
A20: Effective tax rate (%) | B20: =IF(B18=0,"",B19/B18) | C20: =IF(C18=0,"",C19/C18) | D20: =IF(D18=0,"",D19/D18) | E20: =IF(E18=0,"",E19/E18) | F20: =IF(F18=0,"",F19/F18) | G20: =IF(G18=0,"",G19/G18) | H20: =IF(H18=0,"",H19/H18) | I20: =IF(I18=0,"",I19/I18) | ... N20: =IF(N18=0,"",N19/N18)
A21: Profit after tax (PAT) | B21: 257.52 | C21: 263.07 | D21: 375.18 | E21: 270.5 | F21: 288.58 | G21: 664 | H21: =H18-H19 | I21: =I18-I19 | J21: =J18-J19 | K21: =K18-K19 | L21: =L18-L19 | M21: =M18-M19 | N21: =N18-N19
A22: EPS (Rs/share) | B22: =IF('Working Schedules'!B23=0,"",B21/'Working Schedules'!B23) | C22: =IF('Working Schedules'!C23=0,"",C21/'Working Schedules'!C23) | D22: =IF('Working Schedules'!D23=0,"",D21/'Working Schedules'!D23) | E22: =IF('Working Schedules'!E23=0,"",E21/'Working Schedules'!E23) | F22: =IF('Working Schedules'!F23=0,"",F21/'Working Schedules'!F23) | G22: =IF('Working Schedules'!G23=0,"",G21/'Working Schedules'!G23) | H22: =IF('Working Schedules'!H23=0,"",H21/'Working Schedules'!H23) | I22: =IF('Working Schedules'!I23=0,"",I21/'Working Schedules'!I23) | ... N22: =IF('Working Schedules'!N23=0,"",N21/'Working Schedules'!N23)

Sheet Balance Sheet
A1: Navin Fluorine International Ltd | Consolidated Balance Sheet
A2: Rs Crore. Historical FY21-FY25 reconstructed from consolidated annual reports (balances to reported totals); FY26 reconciled to audited results; FY27-FY33 forecast (balances automatically).
A3: Particulars | B3: FY2021A | C3: FY2022A | D3: FY2023A | E3: FY2024A | F3: FY2025A | G3: FY2026A | H3: FY2027E | I3: FY2028E | J3: FY2029E | K3: FY2030E | L3: FY2031E | M3: FY2032E | N3: FY2033E
A4: ASSETS
A5: Net block (PP&E, ROU, intangibles, goodwill) | B5: 540.12 | C5: 556.1 | D5: 1645.88 | E5: 1874.6 | F5: 2741.92 | G5: 3324 | H5: ='Working Schedules'!H8 | I5: ='Working Schedules'!I8 | J5: ='Working Schedules'!J8 | K5: ='Working Schedules'!K8 | L5: ='Working Schedules'!L8 | M5: ='Working Schedules'!M8 | N5: ='Working Schedules'!N8
A6: Capital work-in-progress | B6: 94.87 | C6: 742.1 | D6: 278.58 | E6: 711.09 | F6: 349.79 | G6: 143 | H6: =G6 | I6: =H6 | J6: =I6 | K6: =J6 | L6: =K6 | M6: =L6 | N6: =M6
A7: Non-current investments | B7: 14.54 | C7: 13.92 | D7: 12.7 | E7: 8.79 | F7: 8.12 | G7: 10 | H7: =G7 | I7: =H7 | J7: =I7 | K7: =J7 | L7: =K7 | M7: =L7 | N7: =M7
A8: Other non-current assets | B8: 53.23 | C8: 54.09 | D8: 125.96 | E8: 229.31 | F8: 141.71 | G8: 240 | H8: =G8 | I8: =H8 | J8: =I8 | K8: =J8 | L8: =K8 | M8: =L8 | N8: =M8
A9: Inventories | B9: 180.35 | C9: 257.54 | D9: 468.12 | E9: 371.65 | F9: 322.42 | G9: 428 | H9: ='Working Capital Schedule'!H7 | I9: ='Working Capital Schedule'!I7 | J9: ='Working Capital Schedule'!J7 | K9: ='Working Capital Schedule'!K7 | L9: ='Working Capital Schedule'!L7 | M9: ='Working Capital Schedule'!M7 | N9: ='Working Capital Schedule'!N7
A10: Trade receivables | B10: 284.11 | C10: 357.66 | D10: 561.52 | E10: 512.51 | F10: 582.42 | G10: 753 | H10: ='Working Capital Schedule'!H6 | I10: ='Working Capital Schedule'!I6 | J10: ='Working Capital Schedule'!J6 | K10: ='Working Capital Schedule'!K6 | L10: ='Working Capital Schedule'!L6 | M10: ='Working Capital Schedule'!M6 | N10: ='Working Capital Schedule'!N6
A11: Cash, bank & current investments | B11: 635.43 | C11: 206.39 | D11: 73.8 | E11: 532.43 | F11: 531.2 | G11: 1282 | H11: ='Cash Flow Statement'!H21 | I11: ='Cash Flow Statement'!I21 | J11: ='Cash Flow Statement'!J21 | K11: ='Cash Flow Statement'!K21 | L11: ='Cash Flow Statement'!L21 | M11: ='Cash Flow Statement'!M21 | N11: ='Cash Flow Statement'!N21
A12: Other current assets | B12: 94.85 | C12: 197.68 | D12: 362.73 | E12: 136.62 | F12: 152.8 | G12: 199 | H12: ='Working Capital Schedule'!H8 | I12: ='Working Capital Schedule'!I8 | J12: ='Working Capital Schedule'!J8 | K12: ='Working Capital Schedule'!K8 | L12: ='Working Capital Schedule'!L8 | M12: ='Working Capital Schedule'!M8 | N12: ='Working Capital Schedule'!N8
A13: Total assets | B13: =SUM(B5:B12) | C13: =SUM(C5:C12) | D13: =SUM(D5:D12) | E13: =SUM(E5:E12) | F13: =SUM(F5:F12) | G13: =SUM(G5:G12) | H13: =SUM(H5:H12) | I13: =SUM(I5:I12) | ... N13: =SUM(N5:N12)
A15: EQUITY & LIABILITIES
A16: Equity share capital | B16: 9.9 | C16: 9.91 | D16: 9.91 | E16: 9.91 | F16: 9.92 | G16: 10.25 | H16: =G16 | I16: =H16 | J16: =I16 | K16: =J16 | L16: =K16 | M16: =L16 | N16: =M16
A17: Reserves & surplus | B17: 1624.01 | C17: 1834.31 | D17: 2175.04 | E17: 2372.76 | F17: 2616.31 | G17: 3964 | H17: ='Working Schedules'!H21 | I17: ='Working Schedules'!I21 | J17: ='Working Schedules'!J21 | K17: ='Working Schedules'!K21 | L17: ='Working Schedules'!L21 | M17: ='Working Schedules'!M21 | N17: ='Working Schedules'!N21
A18: Borrowings (incl. lease liabilities) | B18: 2.52 | C18: 120.82 | D18: 860.8 | E18: 1368.46 | F18: 1466.39 | G18: 1272 | H18: ='Working Schedules'!H12 | I18: ='Working Schedules'!I12 | J18: ='Working Schedules'!J12 | K18: ='Working Schedules'!K12 | L18: ='Working Schedules'!L12 | M18: ='Working Schedules'!M12 | N18: ='Working Schedules'!N12
A19: Deferred tax liabilities (net) | B19: 20.74 | C19: 20.14 | D19: 34.75 | E19: 64.33 | F19: 75.41 | G19: 85 | H19: =G19 | I19: =H19 | J19: =I19 | K19: =J19 | L19: =K19 | M19: =L19 | N19: =M19
A20: Other non-current liabilities & provisions | B20: 40.86 | C20: 27.17 | D20: 28.56 | E20: 103.3 | F20: 147.45 | G20: 165 | H20: =G20 | I20: =H20 | J20: =I20 | K20: =J20 | L20: =K20 | M20: =L20 | N20: =M20
A21: Trade payables | B21: 107.42 | C21: 146.53 | D21: 243.48 | E21: 302.5 | F21: 326.96 | G21: 521 | H21: ='Working Capital Schedule'!H9 | I21: ='Working Capital Schedule'!I9 | J21: ='Working Capital Schedule'!J9 | K21: ='Working Capital Schedule'!K9 | L21: ='Working Capital Schedule'!L9 | M21: ='Working Capital Schedule'!M9 | N21: ='Working Capital Schedule'!N9
A22: Other current liabilities & provisions | B22: 92.05 | C22: 226.6 | D22: 176.75 | E22: 155.74 | F22: 187.94 | G22: 361.75 | H22: ='Working Capital Schedule'!H10 | I22: ='Working Capital Schedule'!I10 | J22: ='Working Capital Schedule'!J10 | K22: ='Working Capital Schedule'!K10 | L22: ='Working Capital Schedule'!L10 | M22: ='Working Capital Schedule'!M10 | N22: ='Working Capital Schedule'!N10
A23: Total equity & liabilities | B23: =SUM(B16:B22) | C23: =SUM(C16:C22) | D23: =SUM(D16:D22) | E23: =SUM(E16:E22) | F23: =SUM(F16:F22) | G23: =SUM(G16:G22) | H23: =SUM(H16:H22) | I23: =SUM(I16:I22) | ... N23: =SUM(N16:N22)
A25: Balance check (Assets - Equity & Liab.) | B25: =B13-B23 | C25: =C13-C23 | D25: =D13-D23 | E25: =E13-E23 | F25: =F13-F23 | G25: =G13-G23 | H25: =H13-H23 | I25: =I13-I23 | ... N25: =N13-N23

Sheet Cash Flow Statement
A1: Navin Fluorine International Ltd | Consolidated Cash Flow Statement
A2: Rs Crore. Historical FY21-FY26 as reported (summary); FY27-FY33 forecast via the indirect method, reconciling to the Balance Sheet cash balance.
A3: Particulars | B3: FY2021A | C3: FY2022A | D3: FY2023A | E3: FY2024A | F3: FY2025A | G3: FY2026A | H3: FY2027E | I3: FY2028E | J3: FY2029E | K3: FY2030E | L3: FY2031E | M3: FY2032E | N3: FY2033E
A4: Profit after tax | H4: ='Profit & Loss'!H21 | I4: ='Profit & Loss'!I21 | J4: ='Profit & Loss'!J21 | K4: ='Profit & Loss'!K21 | L4: ='Profit & Loss'!L21 | M4: ='Profit & Loss'!M21 | N4: ='Profit & Loss'!N21
A5: Add: Depreciation & amortisation | H5: ='Profit & Loss'!H12 | I5: ='Profit & Loss'!I12 | J5: ='Profit & Loss'!J12 | K5: ='Profit & Loss'!K12 | L5: ='Profit & Loss'!L12 | M5: ='Profit & Loss'!M12 | N5: ='Profit & Loss'!N12
A6: Add: Finance costs | H6: ='Profit & Loss'!H15 | I6: ='Profit & Loss'!I15 | J6: ='Profit & Loss'!J15 | K6: ='Profit & Loss'!K15 | L6: ='Profit & Loss'!L15 | M6: ='Profit & Loss'!M15 | N6: ='Profit & Loss'!N15
A7: Less: Increase / (decrease) in net working capital | H7: ='Working Capital Schedule'!H12 | I7: ='Working Capital Schedule'!I12 | J7: ='Working Capital Schedule'!J12 | K7: ='Working Capital Schedule'!K12 | L7: ='Working Capital Schedule'!L12 | M7: ='Working Capital Schedule'!M12 | N7: ='Working Capital Schedule'!N12
A8: Cash flow from operating activities | B8: 237.27 | C8: 74.76 | D8: -63.59 | E8: 749.89 | F8: 570.81 | G8: 894 | H8: =H4+H5+H6-H7 | I8: =I4+I5+I6-I7 | J8: =J4+J5+J6-J7 | K8: =K4+K5+K6-K7 | L8: =L4+L5+L6-L7 | M8: =M4+M5+M6-M7 | N8: =N4+N5+N6-N7
A10: Capital expenditure | B10: 98.69 | C10: 578.89 | D10: 757.71 | E10: 732.39 | F10: 561.14 | G10: 490 | H10: =Assumptions!H11 | I10: =Assumptions!I11 | J10: =Assumptions!J11 | K10: =Assumptions!K11 | L10: =Assumptions!L11 | M10: =Assumptions!M11 | N10: =Assumptions!N11
A11: Cash flow from investing activities | B11: -237.1 | C11: -172.37 | D11: -655.62 | E11: -1093.45 | F11: -511.07 | G11: -1235 | H11: =-H10 | I11: =-I10 | J11: =-J10 | K11: =-K10 | L11: =-L10 | M11: =-M10 | N11: =-N10
A13: Change in borrowings | H13: ='Working Schedules'!H12-'Working Schedules'!H11 | I13: ='Working Schedules'!I12-'Working Schedules'!I11 | J13: ='Working Schedules'!J12-'Working Schedules'!J11 | K13: ='Working Schedules'!K12-'Working Schedules'!K11 | L13: ='Working Schedules'!L12-'Working Schedules'!L11 | M13: ='Working Schedules'!M12-'Working Schedules'!M11 | N13: ='Working Schedules'!N12-'Working Schedules'!N11
A14: Less: Interest paid | H14: =-'Profit & Loss'!H15 | I14: =-'Profit & Loss'!I15 | J14: =-'Profit & Loss'!J15 | K14: =-'Profit & Loss'!K15 | L14: =-'Profit & Loss'!L15 | M14: =-'Profit & Loss'!M15 | N14: =-'Profit & Loss'!N15
A15: Less: Dividends paid | H15: =-'Working Schedules'!H19 | I15: =-'Working Schedules'!I19 | J15: =-'Working Schedules'!J19 | K15: =-'Working Schedules'!K19 | L15: =-'Working Schedules'!L19 | M15: =-'Working Schedules'!M19 | N15: =-'Working Schedules'!N19
A16: Add: Equity issuance (QIP) | H16: ='Working Schedules'!H20 | I16: ='Working Schedules'!I20 | J16: ='Working Schedules'!J20 | K16: ='Working Schedules'!K20 | L16: ='Working Schedules'!L20 | M16: ='Working Schedules'!M20 | N16: ='Working Schedules'!N20
A17: Cash flow from financing activities | B17: -45.05 | C17: 41.5 | D17: 657.94 | E17: 335.73 | F17: -46.7 | G17: 344 | H17: =H13+H14+H15+H16 | I17: =I13+I14+I15+I16 | J17: =J13+J14+J15+J16 | K17: =K13+K14+K15+K16 | L17: =L13+L14+L15+L16 | M17: =M13+M14+M15+M16 | N17: =N13+N14+N15+N16
A19: Net increase / (decrease) in cash & investments | B19: =B8+B11+B17 | C19: =C8+C11+C17 | D19: =D8+D11+D17 | E19: =E8+E11+E17 | F19: =F8+F11+F17 | G19: =G8+G11+G17 | H19: =H8+H11+H17 | I19: =I8+I11+I17 | ... N19: =N8+N11+N17
A20: Opening cash & investments | H20: =G21 | I20: =H21 | J20: =I21 | K20: =J21 | L20: =K21 | M20: =L21 | N20: =M21
A21: Closing cash & investments | B21: ='Balance Sheet'!B11 | C21: ='Balance Sheet'!C11 | D21: ='Balance Sheet'!D11 | E21: ='Balance Sheet'!E11 | F21: ='Balance Sheet'!F11 | G21: ='Balance Sheet'!G11 | H21: =H20+H19 | I21: =I20+I19 | J21: =J20+J19 | K21: =K20+K19 | L21: =L20+L19 | M21: =M20+M19 | N21: =N20+N19

Sheet Assumptions
A1: Navin Fluorine International Ltd | Key Assumptions & Forecast Drivers
A2: All figures in Rs Crore unless stated. Blue = hard-coded input | Green = link | Black = formula. Historical columns are derived from reported financials; forecast columns (FY27-33) are driver inputs.
A3: Driver | B3: FY2021A | C3: FY2022A | D3: FY2023A | E3: FY2024A | F3: FY2025A | G3: FY2026A | H3: FY2027E | I3: FY2028E | J3: FY2029E | K3: FY2030E | L3: FY2031E | M3: FY2032E | N3: FY2033E
A5: Revenue growth (%) | C5: =IF('Profit & Loss'!B4=0,"",'Profit & Loss'!C4/'Profit & Loss'!B4-1) | D5: =IF('Profit & Loss'!C4=0,"",'Profit & Loss'!D4/'Profit & Loss'!C4-1) | E5: =IF('Profit & Loss'!D4=0,"",'Profit & Loss'!E4/'Profit & Loss'!D4-1) | F5: =IF('Profit & Loss'!E4=0,"",'Profit & Loss'!F4/'Profit & Loss'!E4-1) | G5: =IF('Profit & Loss'!F4=0,"",'Profit & Loss'!G4/'Profit & Loss'!F4-1) | H5: 0.2 | I5: 0.18 | J5: 0.16 | K5: 0.15 | L5: 0.14 | M5: 0.12 | N5: 0.11
A6: Material cost (% of revenue) | B6: ='Profit & Loss'!B6/'Profit & Loss'!B4 | C6: ='Profit & Loss'!C6/'Profit & Loss'!C4 | D6: ='Profit & Loss'!D6/'Profit & Loss'!D4 | E6: ='Profit & Loss'!E6/'Profit & Loss'!E4 | F6: ='Profit & Loss'!F6/'Profit & Loss'!F4 | G6: ='Profit & Loss'!G6/'Profit & Loss'!G4 | H6: 0.41 | I6: 0.41 | J6: 0.41 | K6: 0.41 | L6: 0.41 | M6: 0.41 | N6: 0.41
A7: Employee cost (% of revenue) | B7: ='Profit & Loss'!B7/'Profit & Loss'!B4 | C7: ='Profit & Loss'!C7/'Profit & Loss'!C4 | D7: ='Profit & Loss'!D7/'Profit & Loss'!D4 | E7: ='Profit & Loss'!E7/'Profit & Loss'!E4 | F7: ='Profit & Loss'!F7/'Profit & Loss'!F4 | G7: ='Profit & Loss'!G7/'Profit & Loss'!G4 | H7: 0.1 | I7: 0.1 | J7: 0.105 | K7: 0.105 | L7: 0.11 | M7: 0.11 | N7: 0.11
A8: Other expenses (% of revenue) | B8: ='Profit & Loss'!B8/'Profit & Loss'!B4 | C8: ='Profit & Loss'!C8/'Profit & Loss'!C4 | D8: ='Profit & Loss'!D8/'Profit & Loss'!D4 | E8: ='Profit & Loss'!E8/'Profit & Loss'!E4 | F8: ='Profit & Loss'!F8/'Profit & Loss'!F4 | G8: ='Profit & Loss'!G8/'Profit & Loss'!G4 | H8: 0.18 | I8: 0.185 | J8: 0.185 | K8: 0.185 | L8: 0.185 | M8: 0.185 | N8: 0.185
A9: Other income (% of revenue) | B9: ='Profit & Loss'!B14/'Profit & Loss'!B4 | C9: ='Profit & Loss'!C14/'Profit & Loss'!C4 | D9: ='Profit & Loss'!D14/'Profit & Loss'!D4 | E9: ='Profit & Loss'!E14/'Profit & Loss'!E4 | F9: ='Profit & Loss'!F14/'Profit & Loss'!F4 | G9: ='Profit & Loss'!G14/'Profit & Loss'!G4 | H9: 0.015 | I9: 0.015 | J9: 0.015 | K9: 0.015 | L9: 0.015 | M9: 0.015 | N9: 0.015
A10: Depreciation (% of opening net block) | C10: =IF('Balance Sheet'!B5=0,"",'Profit & Loss'!C12/'Balance Sheet'!B5) | D10: =IF('Balance Sheet'!C5=0,"",'Profit & Loss'!D12/'Balance Sheet'!C5) | E10: =IF('Balance Sheet'!D5=0,"",'Profit & Loss'!E12/'Balance Sheet'!D5) | F10: =IF('Balance Sheet'!E5=0,"",'Profit & Loss'!F12/'Balance Sheet'!E5) | G10: =IF('Balance Sheet'!F5=0,"",'Profit & Loss'!G12/'Balance Sheet'!F5) | H10: 0.06 | I10: 0.06 | J10: 0.06 | K10: 0.06 | L10: 0.06 | M10: 0.06 | N10: 0.06
A11: Capital expenditure (Rs Cr) | B11: 98.69 | C11: 578.89 | D11: 757.71 | E11: 732.39 | F11: 561.14 | G11: 490 | H11: 600 | I11: 550 | J11: 525 | K11: 500 | L11: 475 | M11: 450 | N11: 450
A12: Effective tax rate (%) | B12: =IF('Profit & Loss'!B18=0,"",'Profit & Loss'!B19/'Profit & Loss'!B18) | C12: =IF('Profit & Loss'!C18=0,"",'Profit & Loss'!C19/'Profit & Loss'!C18) | D12: =IF('Profit & Loss'!D18=0,"",'Profit & Loss'!D19/'Profit & Loss'!D18) | E12: =IF('Profit & Loss'!E18=0,"",'Profit & Loss'!E19/'Profit & Loss'!E18) | F12: =IF('Profit & Loss'!F18=0,"",'Profit & Loss'!F19/'Profit & Loss'!F18) | G12: =IF('Profit & Loss'!G18=0,"",'Profit & Loss'!G19/'Profit & Loss'!G18) | H12: 0.25 | I12: 0.25 | J12: 0.25 | K12: 0.25 | L12: 0.25 | M12: 0.25 | N12: 0.25
A13: Dividend payout ratio (%) | H13: 0.15 | I13: 0.15 | J13: 0.15 | K13: 0.15 | L13: 0.15 | M13: 0.15 | N13: 0.15
A14: Debtor days (on revenue) | B14: ='Balance Sheet'!B10/'Profit & Loss'!B4*365 | C14: ='Balance Sheet'!C10/'Profit & Loss'!C4*365 | D14: ='Balance Sheet'!D10/'Profit & Loss'!D4*365 | E14: ='Balance Sheet'!E10/'Profit & Loss'!E4*365 | F14: ='Balance Sheet'!F10/'Profit & Loss'!F4*365 | G14: ='Balance Sheet'!G10/'Profit & Loss'!G4*365 | H14: 85 | I14: 85 | J14: 85 | K14: 85 | L14: 85 | M14: 85 | N14: 85
A15: Inventory days (on material cost) | B15: ='Balance Sheet'!B9/'Profit & Loss'!B6*365 | C15: ='Balance Sheet'!C9/'Profit & Loss'!C6*365 | D15: ='Balance Sheet'!D9/'Profit & Loss'!D6*365 | E15: ='Balance Sheet'!E9/'Profit & Loss'!E6*365 | F15: ='Balance Sheet'!F9/'Profit & Loss'!F6*365 | G15: ='Balance Sheet'!G9/'Profit & Loss'!G6*365 | H15: 115 | I15: 115 | J15: 115 | K15: 115 | L15: 115 | M15: 115 | N15: 115
A16: Payable days (on material cost) | B16: ='Balance Sheet'!B21/'Profit & Loss'!B6*365 | C16: ='Balance Sheet'!C21/'Profit & Loss'!C6*365 | D16: ='Balance Sheet'!D21/'Profit & Loss'!D6*365 | E16: ='Balance Sheet'!E21/'Profit & Loss'!E6*365 | F16: ='Balance Sheet'!F21/'Profit & Loss'!F6*365 | G16: ='Balance Sheet'!G21/'Profit & Loss'!G6*365 | H16: 130 | I16: 130 | J16: 130 | K16: 130 | L16: 130 | M16: 130 | N16: 130
A17: Other current assets (% of revenue) | B17: ='Balance Sheet'!B12/'Profit & Loss'!B4 | C17: ='Balance Sheet'!C12/'Profit & Loss'!C4 | D17: ='Balance Sheet'!D12/'Profit & Loss'!D4 | E17: ='Balance Sheet'!E12/'Profit & Loss'!E4 | F17: ='Balance Sheet'!F12/'Profit & Loss'!F4 | G17: ='Balance Sheet'!G12/'Profit & Loss'!G4 | H17: 0.06 | I17: 0.06 | J17: 0.06 | K17: 0.06 | L17: 0.06 | M17: 0.06 | N17: 0.06
A18: Other current liabilities (% of revenue) | B18: ='Balance Sheet'!B22/'Profit & Loss'!B4 | C18: ='Balance Sheet'!C22/'Profit & Loss'!C4 | D18: ='Balance Sheet'!D22/'Profit & Loss'!D4 | E18: ='Balance Sheet'!E22/'Profit & Loss'!E4 | F18: ='Balance Sheet'!F22/'Profit & Loss'!F4 | G18: ='Balance Sheet'!G22/'Profit & Loss'!G4 | H18: 0.07 | I18: 0.07 | J18: 0.07 | K18: 0.07 | L18: 0.07 | M18: 0.07 | N18: 0.07
A19: Closing borrowings (Rs Cr) | B19: ='Balance Sheet'!B18 | C19: ='Balance Sheet'!C18 | D19: ='Balance Sheet'!D18 | E19: ='Balance Sheet'!E18 | F19: ='Balance Sheet'!F18 | G19: ='Balance Sheet'!G18 | H19: 1150 | I19: 1000 | J19: 850 | K19: 700 | L19: 600 | M19: 500 | N19: 400
A20: Interest rate on borrowings (%) | C20: =IF('Balance Sheet'!B18=0,"",'Profit & Loss'!C15/(('Balance Sheet'!B18+'Balance Sheet'!C18)/2)) | D20: =IF('Balance Sheet'!C18=0,"",'Profit & Loss'!D15/(('Balance Sheet'!C18+'Balance Sheet'!D18)/2)) | E20: =IF('Balance Sheet'!D18=0,"",'Profit & Loss'!E15/(('Balance Sheet'!D18+'Balance Sheet'!E18)/2)) | F20: =IF('Balance Sheet'!E18=0,"",'Profit & Loss'!F15/(('Balance Sheet'!E18+'Balance Sheet'!F18)/2)) | G20: =IF('Balance Sheet'!F18=0,"",'Profit & Loss'!G15/(('Balance Sheet'!F18+'Balance Sheet'!G18)/2)) | H20: 0.075 | I20: 0.075 | J20: 0.075 | K20: 0.075 | L20: 0.075 | M20: 0.075 | N20: 0.075
A23: Assumption rationale & sources
A24: Revenue growth | B24: FY26 grew 41% on ramp-up of the multi-year specialty/CDMO contract, agro-specialties recovery and HPP (R-32/HFO) scale-up. Forecast tapers 20%->11% (~15% CAGR FY26-33), in line with management's ~20% near-term guidance and brokerage estimates (Motilal Oswal ~20% rev CAGR FY26-28), moderating as the base enlarges. Sources: FY25 AR, Q4FY26 results, earnings calls.
A25: Material cost % of revenue | B25: Held at ~41% (vs 43-45% historical) reflecting a richer mix of high-value HPP/CDMO products that lifted FY26 gross margin. Source: historical consolidated P&L, management commentary on premiumisation.
A26: Employee & other expenses | B26: Modelled as % of revenue near recent levels with mild operating-leverage normalisation; combined with material cost gives EBITDA margin ~29.5-31% (FY26 32.6%, hist 19-26%). Source: historical cost structure, mgmt margin guidance of high-20s%+.
A27: Other income | B27: ~1.5% of revenue, treasury yield on the surplus cash / investments (incl. QIP proceeds). Source: historical other income trend.
A28: Depreciation | B28: Linked to the fixed-asset schedule at ~6.0% of opening net block as CWIP commissions into PP&E. Source: historical depreciation/gross-block relationship.
A29: Capital expenditure | B29: Rs 450-600 Cr p.a. covering announced expansions (Surat HFC/R-32 ~Rs236 Cr, Dahej fluoro-specialty & MPP/cGMP-4 CDMO, agro-specialty). Tapers as the major capex cycle matures. Source: FY25 AR, investor presentations, exchange filings.
A30: Working capital | B30: Debtor ~85d, inventory ~115d, payable ~130d (on material cost) consistent with FY24-26 averages; other CA/CL as % of revenue. Source: historical balance sheets / Screener working-capital history.
A31: Borrowings & interest | B31: Gradual deleveraging post the Rs750 Cr QIP (Jul-2025); closing debt Rs1,150->Rs400 Cr; ~7.5% blended cost on average borrowings. Source: FY26 balance sheet, CARE credit-rating updates.
A32: Tax rate | B32: 25% effective, in line with the new-regime statutory rate (~25.17%) and FY24-26 effective range of 19-24%. Source: historical tax expense.
A33: Dividend payout | B33: 15% of PAT, around the company's historical 12-27% payout band. Source: dividend history.

Sheet Working Capital Schedule
A1: Navin Fluorine International Ltd | Working Capital Schedule
A2: Rs Crore. Operating working capital driven by debtor / inventory / payable days. Feeds the Balance Sheet and Cash Flow Statement.
A3: Particulars | B3: FY2021A | C3: FY2022A | D3: FY2023A | E3: FY2024A | F3: FY2025A | G3: FY2026A | H3: FY2027E | I3: FY2028E | J3: FY2029E | K3: FY2030E | L3: FY2031E | M3: FY2032E | N3: FY2033E
A4: Revenue | B4: ='Profit & Loss'!B4 | C4: ='Profit & Loss'!C4 | D4: ='Profit & Loss'!D4 | E4: ='Profit & Loss'!E4 | F4: ='Profit & Loss'!F4 | G4: ='Profit & Loss'!G4 | H4: ='Profit & Loss'!H4 | I4: ='Profit & Loss'!I4 | ... N4: ='Profit & Loss'!N4
A5: Material cost (COGS) | B5: ='Profit & Loss'!B6 | C5: ='Profit & Loss'!C6 | D5: ='Profit & Loss'!D6 | E5: ='Profit & Loss'!E6 | F5: ='Profit & Loss'!F6 | G5: ='Profit & Loss'!G6 | H5: ='Profit & Loss'!H6 | I5: ='Profit & Loss'!I6 | ... N5: ='Profit & Loss'!N6
A6: Trade receivables | B6: ='Balance Sheet'!B10 | C6: ='Balance Sheet'!C10 | D6: ='Balance Sheet'!D10 | E6: ='Balance Sheet'!E10 | F6: ='Balance Sheet'!F10 | G6: ='Balance Sheet'!G10 | H6: =Assumptions!H14/365*H4 | I6: =Assumptions!I14/365*I4 | J6: =Assumptions!J14/365*J4 | K6: =Assumptions!K14/365*K4 | L6: =Assumptions!L14/365*L4 | M6: =Assumptions!M14/365*M4 | N6: =Assumptions!N14/365*N4
A7: Inventories | B7: ='Balance Sheet'!B9 | C7: ='Balance Sheet'!C9 | D7: ='Balance Sheet'!D9 | E7: ='Balance Sheet'!E9 | F7: ='Balance Sheet'!F9 | G7: ='Balance Sheet'!G9 | H7: =Assumptions!H15/365*H5 | I7: =Assumptions!I15/365*I5 | J7: =Assumptions!J15/365*J5 | K7: =Assumptions!K15/365*K5 | L7: =Assumptions!L15/365*L5 | M7: =Assumptions!M15/365*M5 | N7: =Assumptions!N15/365*N5
A8: Other current assets | B8: ='Balance Sheet'!B12 | C8: ='Balance Sheet'!C12 | D8: ='Balance Sheet'!D12 | E8: ='Balance Sheet'!E12 | F8: ='Balance Sheet'!F12 | G8: ='Balance Sheet'!G12 | H8: =Assumptions!H17*H4 | I8: =Assumptions!I17*I4 | J8: =Assumptions!J17*J4 | K8: =Assumptions!K17*K4 | L8: =Assumptions!L17*L4 | M8: =Assumptions!M17*M4 | N8: =Assumptions!N17*N4
A9: Trade payables | B9: ='Balance Sheet'!B21 | C9: ='Balance Sheet'!C21 | D9: ='Balance Sheet'!D21 | E9: ='Balance Sheet'!E21 | F9: ='Balance Sheet'!F21 | G9: ='Balance Sheet'!G21 | H9: =Assumptions!H16/365*H5 | I9: =Assumptions!I16/365*I5 | J9: =Assumptions!J16/365*J5 | K9: =Assumptions!K16/365*K5 | L9: =Assumptions!L16/365*L5 | M9: =Assumptions!M16/365*M5 | N9: =Assumptions!N16/365*N5
A10: Other current liabilities & provisions | B10: ='Balance Sheet'!B22 | C10: ='Balance Sheet'!C22 | D10: ='Balance Sheet'!D22 | E10: ='Balance Sheet'!E22 | F10: ='Balance Sheet'!F22 | G10: ='Balance Sheet'!G22 | H10: =Assumptions!H18*H4 | I10: =Assumptions!I18*I4 | J10: =Assumptions!J18*J4 | K10: =Assumptions!K18*K4 | L10: =Assumptions!L18*L4 | M10: =Assumptions!M18*M4 | N10: =Assumptions!N18*N4
A11: Net working capital | B11: =B6+B7+B8-B9-B10 | C11: =C6+C7+C8-C9-C10 | D11: =D6+D7+D8-D9-D10 | E11: =E6+E7+E8-E9-E10 | F11: =F6+F7+F8-F9-F10 | G11: =G6+G7+G8-G9-G10 | H11: =H6+H7+H8-H9-H10 | I11: =I6+I7+I8-I9-I10 | ... N11: =N6+N7+N8-N9-N10
A12: Increase / (decrease) in NWC | C12: =C11-B11 | D12: =D11-C11 | E12: =E11-D11 | F12: =F11-E11 | G12: =G11-F11 | H12: =H11-G11 | I12: =I11-H11 | J12: =J11-I11 | ... N12: =N11-M11
A14: Debtor days | B14: =IF(B4=0,"",B6/B4*365) | C14: =IF(C4=0,"",C6/C4*365) | D14: =IF(D4=0,"",D6/D4*365) | E14: =IF(E4=0,"",E6/E4*365) | F14: =IF(F4=0,"",F6/F4*365) | G14: =IF(G4=0,"",G6/G4*365) | H14: =IF(H4=0,"",H6/H4*365) | I14: =IF(I4=0,"",I6/I4*365) | ... N14: =IF(N4=0,"",N6/N4*365)
A15: Inventory days (on COGS) | B15: =IF(B5=0,"",B7/B5*365) | C15: =IF(C5=0,"",C7/C5*365) | D15: =IF(D5=0,"",D7/D5*365) | E15: =IF(E5=0,"",E7/E5*365) | F15: =IF(F5=0,"",F7/F5*365) | G15: =IF(G5=0,"",G7/G5*365) | H15: =IF(H5=0,"",H7/H5*365) | I15: =IF(I5=0,"",I7/I5*365) | ... N15: =IF(N5=0,"",N7/N5*365)
A16: Payable days (on COGS) | B16: =IF(B5=0,"",B9/B5*365) | C16: =IF(C5=0,"",C9/C5*365) | D16: =IF(D5=0,"",D9/D5*365) | E16: =IF(E5=0,"",E9/E5*365) | F16: =IF(F5=0,"",F9/F5*365) | G16: =IF(G5=0,"",G9/G5*365) | H16: =IF(H5=0,"",H9/H5*365) | I16: =IF(I5=0,"",I9/I5*365) | ... N16: =IF(N5=0,"",N9/N5*365)
A17: Cash conversion cycle (days) | B17: =B14+B15-B16 | C17: =C14+C15-C16 | D17: =D14+D15-D16 | E17: =E14+E15-E16 | F17: =F14+F15-F16 | G17: =G14+G15-G16 | H17: =H14+H15-H16 | I17: =I14+I15-I16 | ... N17: =N14+N15-N16

Sheet Working Schedules
A1: Navin Fluorine International Ltd | Supporting Schedules (Fixed Assets, Debt, Equity)
A2: Rs Crore. Fully linked roll-forward schedules feeding the three statements.
B3: FY2021A | C3: FY2022A | D3: FY2023A | E3: FY2024A | F3: FY2025A | G3: FY2026A | H3: FY2027E | I3: FY2028E | J3: FY2029E | K3: FY2030E | L3: FY2031E | M3: FY2032E | N3: FY2033E
A4: Fixed asset & depreciation schedule
A5: Opening net block | C5: =B8 | D5: =C8 | E5: =D8 | F5: =E8 | G5: =F8 | H5: =G8 | I5: =H8 | J5: =I8 | ... N5: =M8
A6: Less: Depreciation & amortisation | B6: ='Profit & Loss'!B12 | C6: ='Profit & Loss'!C12 | D6: ='Profit & Loss'!D12 | E6: ='Profit & Loss'!E12 | F6: ='Profit & Loss'!F12 | G6: ='Profit & Loss'!G12 | H6: =H5*Assumptions!H10 | I6: =I5*Assumptions!I10 | J6: =J5*Assumptions!J10 | K6: =K5*Assumptions!K10 | L6: =L5*Assumptions!L10 | M6: =M5*Assumptions!M10 | N6: =N5*Assumptions!N10
A7: Add: Capital expenditure | C7: =C8-C5+C6 | D7: =D8-D5+D6 | E7: =E8-E5+E6 | F7: =F8-F5+F6 | G7: =G8-G5+G6 | H7: =Assumptions!H11 | I7: =Assumptions!I11 | J7: =Assumptions!J11 | K7: =Assumptions!K11 | L7: =Assumptions!L11 | M7: =Assumptions!M11 | N7: =Assumptions!N11
A8: Closing net block | B8: ='Balance Sheet'!B5 | C8: ='Balance Sheet'!C5 | D8: ='Balance Sheet'!D5 | E8: ='Balance Sheet'!E5 | F8: ='Balance Sheet'!F5 | G8: ='Balance Sheet'!G5 | H8: =H5-H6+H7 | I8: =I5-I6+I7 | J8: =J5-J6+J7 | K8: =K5-K6+K7 | L8: =L5-L6+L7 | M8: =M5-M6+M7 | N8: =N5-N6+N7
A10: Borrowings & interest schedule
A11: Opening borrowings | C11: =B12 | D11: =C12 | E11: =D12 | F11: =E12 | G11: =F12 | H11: =G12 | I11: =H12 | J11: =I12 | ... N11: =M12
A12: Closing borrowings | B12: ='Balance Sheet'!B18 | C12: ='Balance Sheet'!C18 | D12: ='Balance Sheet'!D18 | E12: ='Balance Sheet'!E18 | F12: ='Balance Sheet'!F18 | G12: ='Balance Sheet'!G18 | H12: =Assumptions!H19 | I12: =Assumptions!I19 | J12: =Assumptions!J19 | K12: =Assumptions!K19 | L12: =Assumptions!L19 | M12: =Assumptions!M19 | N12: =Assumptions!N19
A13: Finance costs (interest) | B13: ='Profit & Loss'!B15 | C13: ='Profit & Loss'!C15 | D13: ='Profit & Loss'!D15 | E13: ='Profit & Loss'!E15 | F13: ='Profit & Loss'!F15 | G13: ='Profit & Loss'!G15 | H13: =(H11+H12)/2*Assumptions!H20 | I13: =(I11+I12)/2*Assumptions!I20 | J13: =(J11+J12)/2*Assumptions!J20 | K13: =(K11+K12)/2*Assumptions!K20 | L13: =(L11+L12)/2*Assumptions!L20 | M13: =(M11+M12)/2*Assumptions!M20 | N13: =(N11+N12)/2*Assumptions!N20
A14: Implied interest rate (%) | B14: =IF(B11=0,"",B13/((B11+B12)/2)) | C14: =IF(C11=0,"",C13/((C11+C12)/2)) | D14: =IF(D11=0,"",D13/((D11+D12)/2)) | E14: =IF(E11=0,"",E13/((E11+E12)/2)) | F14: =IF(F11=0,"",F13/((F11+F12)/2)) | G14: =IF(G11=0,"",G13/((G11+G12)/2)) | H14: =IF(H11=0,"",H13/((H11+H12)/2)) | I14: =IF(I11=0,"",I13/((I11+I12)/2)) | ... N14: =IF(N11=0,"",N13/((N11+N12)/2))
A16: Equity & reserves schedule
A17: Opening reserves & surplus | C17: =B21 | D17: =C21 | E17: =D21 | F17: =E21 | G17: =F21 | H17: =G21 | I17: =H21 | J17: =I21 | ... N17: =M21
A18: Add: Profit after tax | B18: ='Profit & Loss'!B21 | C18: ='Profit & Loss'!C21 | D18: ='Profit & Loss'!D21 | E18: ='Profit & Loss'!E21 | F18: ='Profit & Loss'!F21 | G18: ='Profit & Loss'!G21 | H18: ='Profit & Loss'!H21 | I18: ='Profit & Loss'!I21 | ... N18: ='Profit & Loss'!N21
A19: Less: Dividends | C19: =C17+C18+C20-C21 | D19: =D17+D18+D20-D21 | E19: =E17+E18+E20-E21 | F19: =F17+F18+F20-F21 | G19: =G17+G18+G20-G21 | H19: =H18*Assumptions!H13 | I19: =I18*Assumptions!I13 | J19: =J18*Assumptions!J13 | K19: =K18*Assumptions!K13 | L19: =L18*Assumptions!L13 | M19: =M18*Assumptions!M13 | N19: =N18*Assumptions!N13
A20: Add: Equity issuance (QIP) | C20: 0 | D20: 0 | E20: 0 | F20: 0 | G20: =G21-F21-G18+59 | H20: 0 | I20: 0 | J20: 0 | K20: 0 | L20: 0 | M20: 0 | N20: 0
A21: Closing reserves & surplus | B21: ='Balance Sheet'!B17 | C21: ='Balance Sheet'!C17 | D21: ='Balance Sheet'!D17 | E21: ='Balance Sheet'!E17 | F21: ='Balance Sheet'!F17 | G21: ='Balance Sheet'!G17 | H21: =H17+H18-H19+H20 | I21: =I17+I18-I19+I20 | J21: =J17+J18-J19+J20 | K21: =K17+K18-K19+K20 | L21: =L17+L18-L19+L20 | M21: =M17+M18-M19+M20 | N21: =N17+N18-N19+N20
A22: Equity share capital | B22: ='Balance Sheet'!B16 | C22: ='Balance Sheet'!C16 | D22: ='Balance Sheet'!D16 | E22: ='Balance Sheet'!E16 | F22: ='Balance Sheet'!F16 | G22: ='Balance Sheet'!G16 | H22: =G22 | I22: =H22 | J22: =I22 | K22: =J22 | L22: =K22 | M22: =L22 | N22: =M22
A23: No. of equity shares (Cr) | B23: =B22/2 | C23: =C22/2 | D23: =D22/2 | E23: =E22/2 | F23: =F22/2 | G23: =G22/2 | H23: =H22/2 | I23: =I22/2 | ... N23: =N22/2
A25: Net debt summary
A26: Total borrowings | B26: ='Balance Sheet'!B18 | C26: ='Balance Sheet'!C18 | D26: ='Balance Sheet'!D18 | E26: ='Balance Sheet'!E18 | F26: ='Balance Sheet'!F18 | G26: ='Balance Sheet'!G18 | H26: ='Balance Sheet'!H18 | I26: ='Balance Sheet'!I18 | ... N26: ='Balance Sheet'!N18
A27: Less: Cash, bank & current investments | B27: ='Balance Sheet'!B11 | C27: ='Balance Sheet'!C11 | D27: ='Balance Sheet'!D11 | E27: ='Balance Sheet'!E11 | F27: ='Balance Sheet'!F11 | G27: ='Balance Sheet'!G11 | H27: ='Balance Sheet'!H11 | I27: ='Balance Sheet'!I11 | ... N27: ='Balance Sheet'!N11
A28: Net debt / (net cash) | B28: =B26-B27 | C28: =C26-C27 | D28: =D26-D27 | E28: =E26-E27 | F28: =F26-F27 | G28: =G26-G27 | H28: =H26-H27 | I28: =I26-I27 | ... N28: =N26-N27

Sheet Beta Calculation
A1: Navin Fluorine International Ltd | Beta Estimation
